Workbook

Sheet Portada
B2: IGAE México — Escalera de pronóstico 2020
B3: M0 (BVAR Minnesota) → M1 (+Kalman/SV) → M2 (+Partículas/LP) → M3 (+Escenarios epi. + GBM + GDELT)
B5: Corte de información: | C5: 15 de junio de 2020 (15 días tras el cierre de mayo)
B6: Último IGAE oficial conocido al corte: | C6: marzo 2020 (vintage real, rezago de publicación 56 días)
B7: Horizonte de pronóstico: | C7: abril → diciembre 2020
B10: Cómo leer este archivo:
B11: 1) Datos_Niveles: series mensuales reales (INEGI/Banxico/Yahoo Finance/FRED), en niveles.
B12: 2) Transformaciones_MoM: fórmulas EN VIVO (log-diferencia o diferencia simple según la naturaleza de cada serie) sobre Datos_Niveles.
B13: 3) COVID_Escenarios: 4 curvas de crecimiento semanal de casos (fórmulas en vivo desde g0 real y parámetros editables por escenario), con pesos bayesianos de backcast.
B14: 4) GDELT: tono/volumen mensual de noticias sobre México (dato real, GKG 2.1), con z-score en vivo contra su línea base 2017-2019.
B15: 5) Modelos: M0/M1/M2 son SALIDA DE SIMULACIÓN (Monte Carlo bayesiano en Python, no reproducible como fórmulas de hoja de cálculo) y se pegan como valores. M3 SÍ es fórmula en vivo: M2 + ajuste por escenarios epidemiológicos + ajuste por GDELT — cambia si usted cambia g0, los parámetros de escenario, los pesos, o cualquier dato de GDELT.
B16: 6) Graficas: 4 gráficas de banda (una por capa) más una gráfica comparativa de medianas, todas ligadas a la hoja Modelos.
B17: 7) Metodologia: validación cruzada de variables, calendario de publicación (vintage), y hallazgos honestos — incluida la validación NEGATIVA de GDELT y del puente lineal, que se incluyeron en el modelo por instrucción expresa a pesar de no validar en CV.

Sheet Datos_Niveles
A1: Fecha | B1: IGAE | C1: ActividadIndustrial | D1: FBCF | E1: IMCP | F1: ANTAD | G1: AUTOS | H1: TARJETAS | I1: Desempleo | J1: IMSS | K1: EPU | L1: INPC | M1: TC | N1: TIIE | O1: Balanza | P1: BMV | Q1: INDPRO
A2: 2015-01 | B2: 93.11762 | C2: 97.511617 | D2: 99.148794 | E2: 93.868882 | F2: 124.14993 | G2: 89.44452 | H2: 65.82667 | I2: 4.3920326 | J2: 17241108 | K2: 31.711337 | L2: 87.110103 | M2: 14.69259 | N2: 3.0366667 | O2: -563817.5 | P2: 40950.578 | Q2: 102.8905
A3: 2015-02 | B3: 93.471532 | C3: 98.17715 | D3: 96.170012 | E3: 93.973976 | F3: 125.51947 | G3: 90.695334 | H3: 67.54275 | I3: 4.446866 | J3: 17293942 | K3: 22.289471 | L3: 87.275377 | M3: 14.92134 | N3: 3.0594737 | O3: -520528.5 | P3: 44190.172 | Q3: 102.2335
A4: 2015-03 | B4: 93.668156 | C4: 97.659335 | D4: 97.213855 | E4: 94.117753 | F4: 125.66573 | G4: 92.305877 | H4: 68.153847 | I4: 4.2755084 | J4: 17349607 | K4: 37.876565 | L4: 87.630717 | M4: 15.22834 | N4: 3.0747619 | O4: -597025.9 | P4: 43724.781 | Q4: 101.8914
A5: 2015-04 | B5: 94.510996 | C5: 98.741342 | D5: 100.75695 | E5: 94.379032 | F5: 127.49579 | G5: 88.829472 | H5: 68.4709 | I5: 4.3477797 | J5: 17416118 | K5: 18.375568 | L5: 87.40384 | M5: 15.22618 | N5: 3.0435 | O5: -970550.2 | P5: 44582.391 | Q5: 101.3355
A6: 2015-05 | B6: 93.849464 | C6: 97.86853 | D6: 98.662937 | E6: 94.704372 | F6: 127.76549 | G6: 90.183429 | H6: 69.889037 | I6: 4.3854762 | J6: 17471789 | K6: 26.279437 | L6: 86.967366 | M6: 15.26447 | N6: 3.0155 | O6: -1663259.8 | P6: 44703.621 | Q6: 100.8883
A7: 2015-06 | B7: 94.295187 | C7: 98.346397 | D7: 100.79637 | E7: 94.836719 | F7: 129.68775 | G7: 93.681936 | H7: 69.766758 | I7: 4.4134048 | J7: 17538972 | K7: 35.394972 | L7: 87.113108 | M7: 15.48304 | N7: 3.1018182 | O7: -1443773.2 | P7: 45053.699 | Q7: 100.571
A8: 2015-07 | B8: 95.021085 | C8: 99.430547 | D8: 102.70632 | E8: 95.003478 | F8: 130.11828 | G8: 93.864865 | H8: 70.40442 | I8: 4.4911455 | J8: 17598070 | K8: 40.537074 | L8: 87.24082 | M8: 15.93958 | N8: 3.1004348 | O8: -1103614.4 | P8: 44752.93 | Q8: 101.2228
A9: 2015-08 | B9: 94.977833 | C9: 99.76756 | D9: 102.20348 | E9: 95.511374 | F9: 131.81947 | G9: 97.286062 | H9: 72.110447 | I9: 4.3869377 | J9: 17640472 | K9: 51.364435 | L9: 87.424875 | M9: 16.53676 | N9: 3.0771429 | O9: -2296123.8 | P9: 43721.961 | Q9: 101.0367
A10: 2015-09 | B10: 96.430726 | C10: 101.85326 | D10: 103.32771 | E10: 96.292473 | F10: 131.32578 | G10: 97.516194 | H10: 72.759452 | I10: 4.1956663 | J10: 17686088 | K10: 56.28964 | L10: 87.752419 | M10: 16.85776 | N10: 3.067619 | O10: -1253737.3 | P10: 42632.539 | Q10: 100.7547
A11: 2015-10 | B11: 95.238257 | C11: 99.733293 | D11: 99.736359 | E11: 96.624969 | F11: 132.1358 | G11: 98.5115 | H11: 72.54892 | I11: 4.4420062 | J11: 17733890 | K11: 26.353205 | L11: 88.203919 | M11: 16.564 | N11: 3.0440909 | O11: -731876.3 | P11: 44542.762 | Q11: 100.2675
A12: 2015-11 | B12: 94.613741 | C12: 99.00288 | D12: 100.97917 | E12: 96.464578 | F12: 131.85684 | G12: 98.378524 | H12: 76.117284 | I12: 4.0642159 | J12: 17785228 | K12: 13.533063 | L12: 88.685468 | M12: 16.63569 | N12: 3.0721053 | O12: -1716395.3 | P12: 43418.551 | Q12: 99.5298
A13: 2015-12 | B13: 94.891839 | C13: 99.461935 | D13: 98.68828 | E13: 95.769112 | F13: 134.92483 | G13: 99.989888 | H13: 75.297759 | I13: 4.3069323 | J13: 17825380 | K13: 30.036467 | L13: 89.046818 | M13: 17.06662 | N13: 3.2436364 | O13: -1676568 | P13: 42977.5 | Q13: 99.0417
... A73: 2020-12 | B73: 96.098882 | C73: 95.408977 | D73: 82.803234 | E73: 95.312699 | F73: 151.15664 | G73: 71.691365 | H73: 115.47259 | I73: 4.1716719 | J73: 19656358 | K73: 78.497915 | L73: 109.271 | M73: 19.96508 | N73: 4.2931818 | O73: 3593698.7 | P73: 44066.879 | Q73: 98.363
A75: Fuente: INEGI BIE, Banxico SIE, Yahoo Finance (^MXX), FRED (INDPRO). Dato real, sin transformar.

Sheet Transformaciones_MoM
A1: Fecha | B1: IGAE_mom (log-diff) | C1: ActividadIndustrial_mom (log-diff) | D1: FBCF_mom (log-diff) | E1: IMCP_mom (log-diff) | F1: ANTAD_mom (log-diff) | G1: AUTOS_mom (log-diff) | H1: TARJETAS_mom (log-diff) | I1: Desempleo_mom (diff simple) | J1: IMSS_mom (log-diff) | K1: EPU_mom (diff nivel) | L1: INPC_mom (log-diff) | M1: TC_mom (log-diff) | N1: TIIE_mom (diff simple) | O1: Balanza_mom (diff nivel) | P1: BMV_mom (log-diff) | Q1: INDPRO_mom (log-diff)
A2: =Datos_Niveles!A2
A3: =Datos_Niveles!A3 | B3: =LN(Datos_Niveles!B3)-LN(Datos_Niveles!B2) | C3: =LN(Datos_Niveles!C3)-LN(Datos_Niveles!C2) | D3: =LN(Datos_Niveles!D3)-LN(Datos_Niveles!D2) | E3: =LN(Datos_Niveles!E3)-LN(Datos_Niveles!E2) | F3: =LN(Datos_Niveles!F3)-LN(Datos_Niveles!F2) | G3: =LN(Datos_Niveles!G3)-LN(Datos_Niveles!G2) | H3: =LN(Datos_Niveles!H3)-LN(Datos_Niveles!H2) | I3: =Datos_Niveles!I3-Datos_Niveles!I2 | J3: =LN(Datos_Niveles!J3)-LN(Datos_Niveles!J2) | K3: =Datos_Niveles!K3-Datos_Niveles!K2 | L3: =LN(Datos_Niveles!L3)-LN(Datos_Niveles!L2) | M3: =LN(Datos_Niveles!M3)-LN(Datos_Niveles!M2) | N3: =Datos_Niveles!N3-Datos_Niveles!N2 | O3: =Datos_Niveles!O3-Datos_Niveles!O2 | P3: =LN(Datos_Niveles!P3)-LN(Datos_Niveles!P2) | Q3: =LN(Datos_Niveles!Q3)-LN(Datos_Niveles!Q2)
A4: =Datos_Niveles!A4 | B4: =LN(Datos_Niveles!B4)-LN(Datos_Niveles!B3) | C4: =LN(Datos_Niveles!C4)-LN(Datos_Niveles!C3) | D4: =LN(Datos_Niveles!D4)-LN(Datos_Niveles!D3) | E4: =LN(Datos_Niveles!E4)-LN(Datos_Niveles!E3) | F4: =LN(Datos_Niveles!F4)-LN(Datos_Niveles!F3) | G4: =LN(Datos_Niveles!G4)-LN(Datos_Niveles!G3) | H4: =LN(Datos_Niveles!H4)-LN(Datos_Niveles!H3) | I4: =Datos_Niveles!I4-Datos_Niveles!I3 | J4: =LN(Datos_Niveles!J4)-LN(Datos_Niveles!J3) | K4: =Datos_Niveles!K4-Datos_Niveles!K3 | L4: =LN(Datos_Niveles!L4)-LN(Datos_Niveles!L3) | M4: =LN(Datos_Niveles!M4)-LN(Datos_Niveles!M3) | N4: =Datos_Niveles!N4-Datos_Niveles!N3 | O4: =Datos_Niveles!O4-Datos_Niveles!O3 | P4: =LN(Datos_Niveles!P4)-LN(Datos_Niveles!P3) | Q4: =LN(Datos_Niveles!Q4)-LN(Datos_Niveles!Q3)
A5: =Datos_Niveles!A5 | B5: =LN(Datos_Niveles!B5)-LN(Datos_Niveles!B4) | C5: =LN(Datos_Niveles!C5)-LN(Datos_Niveles!C4) | D5: =LN(Datos_Niveles!D5)-LN(Datos_Niveles!D4) | E5: =LN(Datos_Niveles!E5)-LN(Datos_Niveles!E4) | F5: =LN(Datos_Niveles!F5)-LN(Datos_Niveles!F4) | G5: =LN(Datos_Niveles!G5)-LN(Datos_Niveles!G4) | H5: =LN(Datos_Niveles!H5)-LN(Datos_Niveles!H4) | I5: =Datos_Niveles!I5-Datos_Niveles!I4 | J5: =LN(Datos_Niveles!J5)-LN(Datos_Niveles!J4) | K5: =Datos_Niveles!K5-Datos_Niveles!K4 | L5: =LN(Datos_Niveles!L5)-LN(Datos_Niveles!L4) | M5: =LN(Datos_Niveles!M5)-LN(Datos_Niveles!M4) | N5: =Datos_Niveles!N5-Datos_Niveles!N4 | O5: =Datos_Niveles!O5-Datos_Niveles!O4 | P5: =LN(Datos_Niveles!P5)-LN(Datos_Niveles!P4) | Q5: =LN(Datos_Niveles!Q5)-LN(Datos_Niveles!Q4)
A6: =Datos_Niveles!A6 | B6: =LN(Datos_Niveles!B6)-LN(Datos_Niveles!B5) | C6: =LN(Datos_Niveles!C6)-LN(Datos_Niveles!C5) | D6: =LN(Datos_Niveles!D6)-LN(Datos_Niveles!D5) | E6: =LN(Datos_Niveles!E6)-LN(Datos_Niveles!E5) | F6: =LN(Datos_Niveles!F6)-LN(Datos_Niveles!F5) | G6: =LN(Datos_Niveles!G6)-LN(Datos_Niveles!G5) | H6: =LN(Datos_Niveles!H6)-LN(Datos_Niveles!H5) | I6: =Datos_Niveles!I6-Datos_Niveles!I5 | J6: =LN(Datos_Niveles!J6)-LN(Datos_Niveles!J5) | K6: =Datos_Niveles!K6-Datos_Niveles!K5 | L6: =LN(Datos_Niveles!L6)-LN(Datos_Niveles!L5) | M6: =LN(Datos_Niveles!M6)-LN(Datos_Niveles!M5) | N6: =Datos_Niveles!N6-Datos_Niveles!N5 | O6: =Datos_Niveles!O6-Datos_Niveles!O5 | P6: =LN(Datos_Niveles!P6)-LN(Datos_Niveles!P5) | Q6: =LN(Datos_Niveles!Q6)-LN(Datos_Niveles!Q5)
A7: =Datos_Niveles!A7 | B7: =LN(Datos_Niveles!B7)-LN(Datos_Niveles!B6) | C7: =LN(Datos_Niveles!C7)-LN(Datos_Niveles!C6) | D7: =LN(Datos_Niveles!D7)-LN(Datos_Niveles!D6) | E7: =LN(Datos_Niveles!E7)-LN(Datos_Niveles!E6) | F7: =LN(Datos_Niveles!F7)-LN(Datos_Niveles!F6) | G7: =LN(Datos_Niveles!G7)-LN(Datos_Niveles!G6) | H7: =LN(Datos_Niveles!H7)-LN(Datos_Niveles!H6) | I7: =Datos_Niveles!I7-Datos_Niveles!I6 | J7: =LN(Datos_Niveles!J7)-LN(Datos_Niveles!J6) | K7: =Datos_Niveles!K7-Datos_Niveles!K6 | L7: =LN(Datos_Niveles!L7)-LN(Datos_Niveles!L6) | M7: =LN(Datos_Niveles!M7)-LN(Datos_Niveles!M6) | N7: =Datos_Niveles!N7-Datos_Niveles!N6 | O7: =Datos_Niveles!O7-Datos_Niveles!O6 | P7: =LN(Datos_Niveles!P7)-LN(Datos_Niveles!P6) | Q7: =LN(Datos_Niveles!Q7)-LN(Datos_Niveles!Q6)
A8: =Datos_Niveles!A8 | B8: =LN(Datos_Niveles!B8)-LN(Datos_Niveles!B7) | C8: =LN(Datos_Niveles!C8)-LN(Datos_Niveles!C7) | D8: =LN(Datos_Niveles!D8)-LN(Datos_Niveles!D7) | E8: =LN(Datos_Niveles!E8)-LN(Datos_Niveles!E7) | F8: =LN(Datos_Niveles!F8)-LN(Datos_Niveles!F7) | G8: =LN(Datos_Niveles!G8)-LN(Datos_Niveles!G7) | H8: =LN(Datos_Niveles!H8)-LN(Datos_Niveles!H7) | I8: =Datos_Niveles!I8-Datos_Niveles!I7 | J8: =LN(Datos_Niveles!J8)-LN(Datos_Niveles!J7) | K8: =Datos_Niveles!K8-Datos_Niveles!K7 | L8: =LN(Datos_Niveles!L8)-LN(Datos_Niveles!L7) | M8: =LN(Datos_Niveles!M8)-LN(Datos_Niveles!M7) | N8: =Datos_Niveles!N8-Datos_Niveles!N7 | O8: =Datos_Niveles!O8-Datos_Niveles!O7 | P8: =LN(Datos_Niveles!P8)-LN(Datos_Niveles!P7) | Q8: =LN(Datos_Niveles!Q8)-LN(Datos_Niveles!Q7)
A9: =Datos_Niveles!A9 | B9: =LN(Datos_Niveles!B9)-LN(Datos_Niveles!B8) | C9: =LN(Datos_Niveles!C9)-LN(Datos_Niveles!C8) | D9: =LN(Datos_Niveles!D9)-LN(Datos_Niveles!D8) | E9: =LN(Datos_Niveles!E9)-LN(Datos_Niveles!E8) | F9: =LN(Datos_Niveles!F9)-LN(Datos_Niveles!F8) | G9: =LN(Datos_Niveles!G9)-LN(Datos_Niveles!G8) | H9: =LN(Datos_Niveles!H9)-LN(Datos_Niveles!H8) | I9: =Datos_Niveles!I9-Datos_Niveles!I8 | J9: =LN(Datos_Niveles!J9)-LN(Datos_Niveles!J8) | K9: =Datos_Niveles!K9-Datos_Niveles!K8 | L9: =LN(Datos_Niveles!L9)-LN(Datos_Niveles!L8) | M9: =LN(Datos_Niveles!M9)-LN(Datos_Niveles!M8) | N9: =Datos_Niveles!N9-Datos_Niveles!N8 | O9: =Datos_Niveles!O9-Datos_Niveles!O8 | P9: =LN(Datos_Niveles!P9)-LN(Datos_Niveles!P8) | Q9: =LN(Datos_Niveles!Q9)-LN(Datos_Niveles!Q8)
A10: =Datos_Niveles!A10 | B10: =LN(Datos_Niveles!B10)-LN(Datos_Niveles!B9) | C10: =LN(Datos_Niveles!C10)-LN(Datos_Niveles!C9) | D10: =LN(Datos_Niveles!D10)-LN(Datos_Niveles!D9) | E10: =LN(Datos_Niveles!E10)-LN(Datos_Niveles!E9) | F10: =LN(Datos_Niveles!F10)-LN(Datos_Niveles!F9) | G10: =LN(Datos_Niveles!G10)-LN(Datos_Niveles!G9) | H10: =LN(Datos_Niveles!H10)-LN(Datos_Niveles!H9) | I10: =Datos_Niveles!I10-Datos_Niveles!I9 | J10: =LN(Datos_Niveles!J10)-LN(Datos_Niveles!J9) | K10: =Datos_Niveles!K10-Datos_Niveles!K9 | L10: =LN(Datos_Niveles!L10)-LN(Datos_Niveles!L9) | M10: =LN(Datos_Niveles!M10)-LN(Datos_Niveles!M9) | N10: =Datos_Niveles!N10-Datos_Niveles!N9 | O10: =Datos_Niveles!O10-Datos_Niveles!O9 | P10: =LN(Datos_Niveles!P10)-LN(Datos_Niveles!P9) | Q10: =LN(Datos_Niveles!Q10)-LN(Datos_Niveles!Q9)
A11: =Datos_Niveles!A11 | B11: =LN(Datos_Niveles!B11)-LN(Datos_Niveles!B10) | C11: =LN(Datos_Niveles!C11)-LN(Datos_Niveles!C10) | D11: =LN(Datos_Niveles!D11)-LN(Datos_Niveles!D10) | E11: =LN(Datos_Niveles!E11)-LN(Datos_Niveles!E10) | F11: =LN(Datos_Niveles!F11)-LN(Datos_Niveles!F10) | G11: =LN(Datos_Niveles!G11)-LN(Datos_Niveles!G10) | H11: =LN(Datos_Niveles!H11)-LN(Datos_Niveles!H10) | I11: =Datos_Niveles!I11-Datos_Niveles!I10 | J11: =LN(Datos_Niveles!J11)-LN(Datos_Niveles!J10) | K11: =Datos_Niveles!K11-Datos_Niveles!K10 | L11: =LN(Datos_Niveles!L11)-LN(Datos_Niveles!L10) | M11: =LN(Datos_Niveles!M11)-LN(Datos_Niveles!M10) | N11: =Datos_Niveles!N11-Datos_Niveles!N10 | O11: =Datos_Niveles!O11-Datos_Niveles!O10 | P11: =LN(Datos_Niveles!P11)-LN(Datos_Niveles!P10) | Q11: =LN(Datos_Niveles!Q11)-LN(Datos_Niveles!Q10)
A12: =Datos_Niveles!A12 | B12: =LN(Datos_Niveles!B12)-LN(Datos_Niveles!B11) | C12: =LN(Datos_Niveles!C12)-LN(Datos_Niveles!C11) | D12: =LN(Datos_Niveles!D12)-LN(Datos_Niveles!D11) | E12: =LN(Datos_Niveles!E12)-LN(Datos_Niveles!E11) | F12: =LN(Datos_Niveles!F12)-LN(Datos_Niveles!F11) | G12: =LN(Datos_Niveles!G12)-LN(Datos_Niveles!G11) | H12: =LN(Datos_Niveles!H12)-LN(Datos_Niveles!H11) | I12: =Datos_Niveles!I12-Datos_Niveles!I11 | J12: =LN(Datos_Niveles!J12)-LN(Datos_Niveles!J11) | K12: =Datos_Niveles!K12-Datos_Niveles!K11 | L12: =LN(Datos_Niveles!L12)-LN(Datos_Niveles!L11) | M12: =LN(Datos_Niveles!M12)-LN(Datos_Niveles!M11) | N12: =Datos_Niveles!N12-Datos_Niveles!N11 | O12: =Datos_Niveles!O12-Datos_Niveles!O11 | P12: =LN(Datos_Niveles!P12)-LN(Datos_Niveles!P11) | Q12: =LN(Datos_Niveles!Q12)-LN(Datos_Niveles!Q11)
A13: =Datos_Niveles!A13 | B13: =LN(Datos_Niveles!B13)-LN(Datos_Niveles!B12) | C13: =LN(Datos_Niveles!C13)-LN(Datos_Niveles!C12) | D13: =LN(Datos_Niveles!D13)-LN(Datos_Niveles!D12) | E13: =LN(Datos_Niveles!E13)-LN(Datos_Niveles!E12) | F13: =LN(Datos_Niveles!F13)-LN(Datos_Niveles!F12) | G13: =LN(Datos_Niveles!G13)-LN(Datos_Niveles!G12) | H13: =LN(Datos_Niveles!H13)-LN(Datos_Niveles!H12) | I13: =Datos_Niveles!I13-Datos_Niveles!I12 | J13: =LN(Datos_Niveles!J13)-LN(Datos_Niveles!J12) | K13: =Datos_Niveles!K13-Datos_Niveles!K12 | L13: =LN(Datos_Niveles!L13)-LN(Datos_Niveles!L12) | M13: =LN(Datos_Niveles!M13)-LN(Datos_Niveles!M12) | N13: =Datos_Niveles!N13-Datos_Niveles!N12 | O13: =Datos_Niveles!O13-Datos_Niveles!O12 | P13: =LN(Datos_Niveles!P13)-LN(Datos_Niveles!P12) | Q13: =LN(Datos_Niveles!Q13)-LN(Datos_Niveles!Q12)
A14: =Datos_Niveles!A14 | B14: =LN(Datos_Niveles!B14)-LN(Datos_Niveles!B13) | C14: =LN(Datos_Niveles!C14)-LN(Datos_Niveles!C13) | D14: =LN(Datos_Niveles!D14)-LN(Datos_Niveles!D13) | E14: =LN(Datos_Niveles!E14)-LN(Datos_Niveles!E13) | F14: =LN(Datos_Niveles!F14)-LN(Datos_Niveles!F13) | G14: =LN(Datos_Niveles!G14)-LN(Datos_Niveles!G13) | H14: =LN(Datos_Niveles!H14)-LN(Datos_Niveles!H13) | I14: =Datos_Niveles!I14-Datos_Niveles!I13 | J14: =LN(Datos_Niveles!J14)-LN(Datos_Niveles!J13) | K14: =Datos_Niveles!K14-Datos_Niveles!K13 | L14: =LN(Datos_Niveles!L14)-LN(Datos_Niveles!L13) | M14: =LN(Datos_Niveles!M14)-LN(Datos_Niveles!M13) | N14: =Datos_Niveles!N14-Datos_Niveles!N13 | O14: =Datos_Niveles!O14-Datos_Niveles!O13 | P14: =LN(Datos_Niveles!P14)-LN(Datos_Niveles!P13) | Q14: =LN(Datos_Niveles!Q14)-LN(Datos_Niveles!Q13)
... A73: =Datos_Niveles!A73 | B73: =LN(Datos_Niveles!B73)-LN(Datos_Niveles!B72) | C73: =LN(Datos_Niveles!C73)-LN(Datos_Niveles!C72) | D73: =LN(Datos_Niveles!D73)-LN(Datos_Niveles!D72) | E73: =LN(Datos_Niveles!E73)-LN(Datos_Niveles!E72) | F73: =LN(Datos_Niveles!F73)-LN(Datos_Niveles!F72) | G73: =LN(Datos_Niveles!G73)-LN(Datos_Niveles!G72) | H73: =LN(Datos_Niveles!H73)-LN(Datos_Niveles!H72) | I73: =Datos_Niveles!I73-Datos_Niveles!I72 | J73: =LN(Datos_Niveles!J73)-LN(Datos_Niveles!J72) | K73: =Datos_Niveles!K73-Datos_Niveles!K72 | L73: =LN(Datos_Niveles!L73)-LN(Datos_Niveles!L72) | M73: =LN(Datos_Niveles!M73)-LN(Datos_Niveles!M72) | N73: =Datos_Niveles!N73-Datos_Niveles!N72 | O73: =Datos_Niveles!O73-Datos_Niveles!O72 | P73: =LN(Datos_Niveles!P73)-LN(Datos_Niveles!P72) | Q73: =LN(Datos_Niveles!Q73)-LN(Datos_Niveles!Q72)
A75: Regla: índices/niveles de actividad → log-diferencia mensual; tasas ya en % → diferencia simple; balanza/EPU (pueden ser negativos) → diferencia simple en nivel. Fórmulas EN VIVO sobre Datos_Niveles.

Sheet COVID_Escenarios
A1: Escenarios epidemiológicos — crecimiento semanal de casos, México
A3: g0 (tasa de crecimiento semanal real al corte, dato observado) | D3: 0.13068831
A4: Fuente: Our World in Data, semana terminada 2020-06-14, log(casos_t/casos_t-1).
A6: Parámetros de escenario (editables)
A7: Escenario | B7: g_inf (tasa largo plazo) | C7: tau (semanas) | D7: bump_semana | E7: bump_amplitud | F7: bump_ancho
A8: nueva_ola | B8: -0.02 | C8: 10 | D8: 22 | E8: 0.1 | F8: 3
A9: rebote_lento | B9: -0.02 | C9: 16 | E9: 0 | F9: 1
A10: rebote_rapido | B10: -0.1 | C10: 3 | E10: 0 | F10: 1
A11: meseta_extendida | B11: 0 | C11: 26 | E11: 0 | F11: 1
A14: Semana (t, 0=corte) | B14: nueva_ola | C14: rebote_lento | D14: rebote_rapido | E14: meseta_extendida | F14: g_observado (real, solo t<0)
A15: -4 | B15: =ROUND($B$8+($D$3-$B$8)*EXP(-A15/$C$8)+IF($D$8="",0,$E$8*EXP(-0.5*((A15-$D$8)/$F$8)^2)),6) | C15: =ROUND($B$9+($D$3-$B$9)*EXP(-A15/$C$9)+IF($D$9="",0,$E$9*EXP(-0.5*((A15-$D$9)/$F$9)^2)),6) | D15: =ROUND($B$10+($D$3-$B$10)*EXP(-A15/$C$10)+IF($D$10="",0,$E$10*EXP(-0.5*((A15-$D$10)/$F$10)^2)),6) | E15: =ROUND($B$11+($D$3-$B$11)*EXP(-A15/$C$11)+IF($D$11="",0,$E$11*EXP(-0.5*((A15-$D$11)/$F$11)^2)),6) | F15: 0.21345401
A16: -3 | B16: =ROUND($B$8+($D$3-$B$8)*EXP(-A16/$C$8)+IF($D$8="",0,$E$8*EXP(-0.5*((A16-$D$8)/$F$8)^2)),6) | C16: =ROUND($B$9+($D$3-$B$9)*EXP(-A16/$C$9)+IF($D$9="",0,$E$9*EXP(-0.5*((A16-$D$9)/$F$9)^2)),6) | D16: =ROUND($B$10+($D$3-$B$10)*EXP(-A16/$C$10)+IF($D$10="",0,$E$10*EXP(-0.5*((A16-$D$10)/$F$10)^2)),6) | E16: =ROUND($B$11+($D$3-$B$11)*EXP(-A16/$C$11)+IF($D$11="",0,$E$11*EXP(-0.5*((A16-$D$11)/$F$11)^2)),6) | F16: 0.10902107
A17: -2 | B17: =ROUND($B$8+($D$3-$B$8)*EXP(-A17/$C$8)+IF($D$8="",0,$E$8*EXP(-0.5*((A17-$D$8)/$F$8)^2)),6) | C17: =ROUND($B$9+($D$3-$B$9)*EXP(-A17/$C$9)+IF($D$9="",0,$E$9*EXP(-0.5*((A17-$D$9)/$F$9)^2)),6) | D17: =ROUND($B$10+($D$3-$B$10)*EXP(-A17/$C$10)+IF($D$10="",0,$E$10*EXP(-0.5*((A17-$D$10)/$F$10)^2)),6) | E17: =ROUND($B$11+($D$3-$B$11)*EXP(-A17/$C$11)+IF($D$11="",0,$E$11*EXP(-0.5*((A17-$D$11)/$F$11)^2)),6) | F17: 0.1247247
A18: -1 | B18: =ROUND($B$8+($D$3-$B$8)*EXP(-A18/$C$8)+IF($D$8="",0,$E$8*EXP(-0.5*((A18-$D$8)/$F$8)^2)),6) | C18: =ROUND($B$9+($D$3-$B$9)*EXP(-A18/$C$9)+IF($D$9="",0,$E$9*EXP(-0.5*((A18-$D$9)/$F$9)^2)),6) | D18: =ROUND($B$10+($D$3-$B$10)*EXP(-A18/$C$10)+IF($D$10="",0,$E$10*EXP(-0.5*((A18-$D$10)/$F$10)^2)),6) | E18: =ROUND($B$11+($D$3-$B$11)*EXP(-A18/$C$11)+IF($D$11="",0,$E$11*EXP(-0.5*((A18-$D$11)/$F$11)^2)),6) | F18: 0.13068831
A19: 0 | B19: =ROUND($B$8+($D$3-$B$8)*EXP(-A19/$C$8)+IF($D$8="",0,$E$8*EXP(-0.5*((A19-$D$8)/$F$8)^2)),6) | C19: =ROUND($B$9+($D$3-$B$9)*EXP(-A19/$C$9)+IF($D$9="",0,$E$9*EXP(-0.5*((A19-$D$9)/$F$9)^2)),6) | D19: =ROUND($B$10+($D$3-$B$10)*EXP(-A19/$C$10)+IF($D$10="",0,$E$10*EXP(-0.5*((A19-$D$10)/$F$10)^2)),6) | E19: =ROUND($B$11+($D$3-$B$11)*EXP(-A19/$C$11)+IF($D$11="",0,$E$11*EXP(-0.5*((A19-$D$11)/$F$11)^2)),6)
A20: 1 | B20: =ROUND($B$8+($D$3-$B$8)*EXP(-A20/$C$8)+IF($D$8="",0,$E$8*EXP(-0.5*((A20-$D$8)/$F$8)^2)),6) | C20: =ROUND($B$9+($D$3-$B$9)*EXP(-A20/$C$9)+IF($D$9="",0,$E$9*EXP(-0.5*((A20-$D$9)/$F$9)^2)),6) | D20: =ROUND($B$10+($D$3-$B$10)*EXP(-A20/$C$10)+IF($D$10="",0,$E$10*EXP(-0.5*((A20-$D$10)/$F$10)^2)),6) | E20: =ROUND($B$11+($D$3-$B$11)*EXP(-A20/$C$11)+IF($D$11="",0,$E$11*EXP(-0.5*((A20-$D$11)/$F$11)^2)),6)
A21: 2 | B21: =ROUND($B$8+($D$3-$B$8)*EXP(-A21/$C$8)+IF($D$8="",0,$E$8*EXP(-0.5*((A21-$D$8)/$F$8)^2)),6) | C21: =ROUND($B$9+($D$3-$B$9)*EXP(-A21/$C$9)+IF($D$9="",0,$E$9*EXP(-0.5*((A21-$D$9)/$F$9)^2)),6) | D21: =ROUND($B$10+($D$3-$B$10)*EXP(-A21/$C$10)+IF($D$10="",0,$E$10*EXP(-0.5*((A21-$D$10)/$F$10)^2)),6) | E21: =ROUND($B$11+($D$3-$B$11)*EXP(-A21/$C$11)+IF($D$11="",0,$E$11*EXP(-0.5*((A21-$D$11)/$F$11)^2)),6)
A22: 3 | B22: =ROUND($B$8+($D$3-$B$8)*EXP(-A22/$C$8)+IF($D$8="",0,$E$8*EXP(-0.5*((A22-$D$8)/$F$8)^2)),6) | C22: =ROUND($B$9+($D$3-$B$9)*EXP(-A22/$C$9)+IF($D$9="",0,$E$9*EXP(-0.5*((A22-$D$9)/$F$9)^2)),6) | D22: =ROUND($B$10+($D$3-$B$10)*EXP(-A22/$C$10)+IF($D$10="",0,$E$10*EXP(-0.5*((A22-$D$10)/$F$10)^2)),6) | E22: =ROUND($B$11+($D$3-$B$11)*EXP(-A22/$C$11)+IF($D$11="",0,$E$11*EXP(-0.5*((A22-$D$11)/$F$11)^2)),6)
A23: 4 | B23: =ROUND($B$8+($D$3-$B$8)*EXP(-A23/$C$8)+IF($D$8="",0,$E$8*EXP(-0.5*((A23-$D$8)/$F$8)^2)),6) | C23: =ROUND($B$9+($D$3-$B$9)*EXP(-A23/$C$9)+IF($D$9="",0,$E$9*EXP(-0.5*((A23-$D$9)/$F$9)^2)),6) | D23: =ROUND($B$10+($D$3-$B$10)*EXP(-A23/$C$10)+IF($D$10="",0,$E$10*EXP(-0.5*((A23-$D$10)/$F$10)^2)),6) | E23: =ROUND($B$11+($D$3-$B$11)*EXP(-A23/$C$11)+IF($D$11="",0,$E$11*EXP(-0.5*((A23-$D$11)/$F$11)^2)),6)
A24: 5 | B24: =ROUND($B$8+($D$3-$B$8)*EXP(-A24/$C$8)+IF($D$8="",0,$E$8*EXP(-0.5*((A24-$D$8)/$F$8)^2)),6) | C24: =ROUND($B$9+($D$3-$B$9)*EXP(-A24/$C$9)+IF($D$9="",0,$E$9*EXP(-0.5*((A24-$D$9)/$F$9)^2)),6) | D24: =ROUND($B$10+($D$3-$B$10)*EXP(-A24/$C$10)+IF($D$10="",0,$E$10*EXP(-0.5*((A24-$D$10)/$F$10)^2)),6) | E24: =ROUND($B$11+($D$3-$B$11)*EXP(-A24/$C$11)+IF($D$11="",0,$E$11*EXP(-0.5*((A24-$D$11)/$F$11)^2)),6)
A25: 6 | B25: =ROUND($B$8+($D$3-$B$8)*EXP(-A25/$C$8)+IF($D$8="",0,$E$8*EXP(-0.5*((A25-$D$8)/$F$8)^2)),6) | C25: =ROUND($B$9+($D$3-$B$9)*EXP(-A25/$C$9)+IF($D$9="",0,$E$9*EXP(-0.5*((A25-$D$9)/$F$9)^2)),6) | D25: =ROUND($B$10+($D$3-$B$10)*EXP(-A25/$C$10)+IF($D$10="",0,$E$10*EXP(-0.5*((A25-$D$10)/$F$10)^2)),6) | E25: =ROUND($B$11+($D$3-$B$11)*EXP(-A25/$C$11)+IF($D$11="",0,$E$11*EXP(-0.5*((A25-$D$11)/$F$11)^2)),6)
A26: 7 | B26: =ROUND($B$8+($D$3-$B$8)*EXP(-A26/$C$8)+IF($D$8="",0,$E$8*EXP(-0.5*((A26-$D$8)/$F$8)^2)),6) | C26: =ROUND($B$9+($D$3-$B$9)*EXP(-A26/$C$9)+IF($D$9="",0,$E$9*EXP(-0.5*((A26-$D$9)/$F$9)^2)),6) | D26: =ROUND($B$10+($D$3-$B$10)*EXP(-A26/$C$10)+IF($D$10="",0,$E$10*EXP(-0.5*((A26-$D$10)/$F$10)^2)),6) | E26: =ROUND($B$11+($D$3-$B$11)*EXP(-A26/$C$11)+IF($D$11="",0,$E$11*EXP(-0.5*((A26-$D$11)/$F$11)^2)),6)
A27: 8 | B27: =ROUND($B$8+($D$3-$B$8)*EXP(-A27/$C$8)+IF($D$8="",0,$E$8*EXP(-0.5*((A27-$D$8)/$F$8)^2)),6) | C27: =ROUND($B$9+($D$3-$B$9)*EXP(-A27/$C$9)+IF($D$9="",0,$E$9*EXP(-0.5*((A27-$D$9)/$F$9)^2)),6) | D27: =ROUND($B$10+($D$3-$B$10)*EXP(-A27/$C$10)+IF($D$10="",0,$E$10*EXP(-0.5*((A27-$D$10)/$F$10)^2)),6) | E27: =ROUND($B$11+($D$3-$B$11)*EXP(-A27/$C$11)+IF($D$11="",0,$E$11*EXP(-0.5*((A27-$D$11)/$F$11)^2)),6)
A28: 9 | B28: =ROUND($B$8+($D$3-$B$8)*EXP(-A28/$C$8)+IF($D$8="",0,$E$8*EXP(-0.5*((A28-$D$8)/$F$8)^2)),6) | C28: =ROUND($B$9+($D$3-$B$9)*EXP(-A28/$C$9)+IF($D$9="",0,$E$9*EXP(-0.5*((A28-$D$9)/$F$9)^2)),6) | D28: =ROUND($B$10+($D$3-$B$10)*EXP(-A28/$C$10)+IF($D$10="",0,$E$10*EXP(-0.5*((A28-$D$10)/$F$10)^2)),6) | E28: =ROUND($B$11+($D$3-$B$11)*EXP(-A28/$C$11)+IF($D$11="",0,$E$11*EXP(-0.5*((A28-$D$11)/$F$11)^2)),6)
A29: 10 | B29: =ROUND($B$8+($D$3-$B$8)*EXP(-A29/$C$8)+IF($D$8="",0,$E$8*EXP(-0.5*((A29-$D$8)/$F$8)^2)),6) | C29: =ROUND($B$9+($D$3-$B$9)*EXP(-A29/$C$9)+IF($D$9="",0,$E$9*EXP(-0.5*((A29-$D$9)/$F$9)^2)),6) | D29: =ROUND($B$10+($D$3-$B$10)*EXP(-A29/$C$10)+IF($D$10="",0,$E$10*EXP(-0.5*((A29-$D$10)/$F$10)^2)),6) | E29: =ROUND($B$11+($D$3-$B$11)*EXP(-A29/$C$11)+IF($D$11="",0,$E$11*EXP(-0.5*((A29-$D$11)/$F$11)^2)),6)
A30: 11 | B30: =ROUND($B$8+($D$3-$B$8)*EXP(-A30/$C$8)+IF($D$8="",0,$E$8*EXP(-0.5*((A30-$D$8)/$F$8)^2)),6) | C30: =ROUND($B$9+($D$3-$B$9)*EXP(-A30/$C$9)+IF($D$9="",0,$E$9*EXP(-0.5*((A30-$D$9)/$F$9)^2)),6) | D30: =ROUND($B$10+($D$3-$B$10)*EXP(-A30/$C$10)+IF($D$10="",0,$E$10*EXP(-0.5*((A30-$D$10)/$F$10)^2)),6) | E30: =ROUND($B$11+($D$3-$B$11)*EXP(-A30/$C$11)+IF($D$11="",0,$E$11*EXP(-0.5*((A30-$D$11)/$F$11)^2)),6)
... A47: 28 | B47: =ROUND($B$8+($D$3-$B$8)*EXP(-A47/$C$8)+IF($D$8="",0,$E$8*EXP(-0.5*((A47-$D$8)/$F$8)^2)),6) | C47: =ROUND($B$9+($D$3-$B$9)*EXP(-A47/$C$9)+IF($D$9="",0,$E$9*EXP(-0.5*((A47-$D$9)/$F$9)^2)),6) | D47: =ROUND($B$10+($D$3-$B$10)*EXP(-A47/$C$10)+IF($D$10="",0,$E$10*EXP(-0.5*((A47-$D$10)/$F$10)^2)),6) | E47: =ROUND($B$11+($D$3-$B$11)*EXP(-A47/$C$11)+IF($D$11="",0,$E$11*EXP(-0.5*((A47-$D$11)/$F$11)^2)),6)
A49: Verosimilitud de backcast (t=-4..-1) y peso bayesiano
A50: tau_verosimilitud | B50: 0.04
A52: Escenario | B52: logLik backcast | C52: peso bayesiano
A53: nueva_ola | B53: =-0.5*SUMPRODUCT(((F15:F18)-(B15:B18))^2)/$B$50^2 | C53: =EXP(B53-MAX($B$53:$B$56))/SUMPRODUCT(EXP($B$53:$B$56-MAX($B$53:$B$56)))
A54: rebote_lento | B54: =-0.5*SUMPRODUCT(((F15:F18)-(C15:C18))^2)/$B$50^2 | C54: =EXP(B54-MAX($B$53:$B$56))/SUMPRODUCT(EXP($B$53:$B$56-MAX($B$53:$B$56)))
A55: rebote_rapido | B55: =-0.5*SUMPRODUCT(((F15:F18)-(D15:D18))^2)/$B$50^2 | C55: =EXP(B55-MAX($B$53:$B$56))/SUMPRODUCT(EXP($B$53:$B$56-MAX($B$53:$B$56)))
A56: meseta_extendida | B56: =-0.5*SUMPRODUCT(((F15:F18)-(E15:E18))^2)/$B$50^2 | C56: =EXP(B56-MAX($B$53:$B$56))/SUMPRODUCT(EXP($B$53:$B$56-MAX($B$53:$B$56)))
A59: Presión de casos mensual (log-nivel acumulado relativo al corte)
A60: Mes | B60: nueva_ola | C60: rebote_lento | D60: rebote_rapido | E60: meseta_extendida | F60: semana efectiva (MAX(0,·))
A61: 2020-04 | B61: =IF(F61<0,0,SUMIF($A$19:$A$47,"<="&F61,B$19:B$47)) | C61: =IF(F61<0,0,SUMIF($A$19:$A$47,"<="&F61,C$19:C$47)) | D61: =IF(F61<0,0,SUMIF($A$19:$A$47,"<="&F61,D$19:D$47)) | E61: =IF(F61<0,0,SUMIF($A$19:$A$47,"<="&F61,E$19:E$47)) | F61: -6.571
A62: 2020-05 | B62: =IF(F62<0,0,SUMIF($A$19:$A$47,"<="&F62,B$19:B$47)) | C62: =IF(F62<0,0,SUMIF($A$19:$A$47,"<="&F62,C$19:C$47)) | D62: =IF(F62<0,0,SUMIF($A$19:$A$47,"<="&F62,D$19:D$47)) | E62: =IF(F62<0,0,SUMIF($A$19:$A$47,"<="&F62,E$19:E$47)) | F62: -2.143
A63: 2020-06 | B63: =IF(F63<0,0,SUMIF($A$19:$A$47,"<="&F63,B$19:B$47)) | C63: =IF(F63<0,0,SUMIF($A$19:$A$47,"<="&F63,C$19:C$47)) | D63: =IF(F63<0,0,SUMIF($A$19:$A$47,"<="&F63,D$19:D$47)) | E63: =IF(F63<0,0,SUMIF($A$19:$A$47,"<="&F63,E$19:E$47)) | F63: 2.143
A64: 2020-07 | B64: =IF(F64<0,0,SUMIF($A$19:$A$47,"<="&F64,B$19:B$47)) | C64: =IF(F64<0,0,SUMIF($A$19:$A$47,"<="&F64,C$19:C$47)) | D64: =IF(F64<0,0,SUMIF($A$19:$A$47,"<="&F64,D$19:D$47)) | E64: =IF(F64<0,0,SUMIF($A$19:$A$47,"<="&F64,E$19:E$47)) | F64: 6.571
...

Sheet GDELT
A1: GDELT GKG 2.1 — tono de noticias sobre México (dato real, muestreo 2 slices/día, 1 día/mes)
A2: Muestreo reducido respecto al plan original (4-8 slices/día) por costo de tiempo de cómputo en la sesión. CV5 R² contra el residuo del VAR: -0.21 (media) / -0.19 (varianza) — NO validó, pero se incluye en el modelo por instrucción expresa (ver Modelos!M3 y Metodologia).
A4: Fecha | B4: n_articulos_MX | C4: tono_promedio | D4: polaridad_promedio | E4: z_tono (vs. línea base)
A5: 2017-01 | B5: 60 | C5: -0.49312252 | D5: 5.3587613 | E5: =(C5-$C$54)/$C$55
A6: 2017-02 | B6: 157 | C6: -0.72968075 | D6: 6.0789124 | E6: =(C6-$C$54)/$C$55
A7: 2017-03 | B7: 193 | C7: -0.058867762 | D7: 5.9697456 | E7: =(C7-$C$54)/$C$55
A8: 2017-04 | B8: 77 | C8: 0.85931515 | D8: 6.7107386 | E8: =(C8-$C$54)/$C$55
A9: 2017-05 | B9: 118 | C9: -0.68560836 | D9: 6.6295108 | E9: =(C9-$C$54)/$C$55
A10: 2017-06 | B10: 57 | C10: -1.0341208 | D10: 6.5598266 | E10: =(C10-$C$54)/$C$55
A11: 2017-07 | B11: 116 | C11: -1.9133315 | D11: 6.3480984 | E11: =(C11-$C$54)/$C$55
A12: 2017-08 | B12: 134 | C12: -1.8900446 | D12: 6.8907407 | E12: =(C12-$C$54)/$C$55
A13: 2017-09 | B13: 112 | C13: -1.3551776 | D13: 6.2450415 | E13: =(C13-$C$54)/$C$55
A14: 2017-10 | B14: 22 | C14: -0.4990357 | D14: 7.208547 | E14: =(C14-$C$54)/$C$55
A15: 2017-11 | B15: 139 | C15: -2.1831477 | D15: 7.0442711 | E15: =(C15-$C$54)/$C$55
A16: 2017-12 | B16: 187 | C16: -3.5938295 | D16: 8.2527035 | E16: =(C16-$C$54)/$C$55
... A52: 2020-12 | B52: 53 | C52: -1.0325232 | D52: 5.9220109 | E52: =(C52-$C$54)/$C$55
A54: Línea base 2017-2019 (media) | C54: =AVERAGE(C5:C40)
A55: Línea base 2017-2019 (desv. estándar) | C55: =STDEV(C5:C40)

Sheet Modelos
A1: Modelos M0-M3 — mediana y bandas de incertidumbre, abril-diciembre 2020
A2: M0/M1/M2 = salida de simulación Monte Carlo (Python, valores pegados). M3 = fórmula EN VIVO: M2 + ajuste por escenarios epidemiológicos (hoja COVID_Escenarios) + ajuste por GDELT (hoja GDELT), con coeficientes editables abajo.
A4: Coeficientes de M3 (editables)
A5: TILT_COEF (inclinación por escenario epi, fracción de sqrt(s0)) | C5: 0.3
A6: VAR_COEF (varianza por dispersión de escenarios) | C6: 0.3
A7: GDELT_TILT_COEF (inclinación por z-score GDELT) | C7: 0.3
A8: GDELT_VAR_COEF (varianza por |z-score| GDELT) | C8: 0.25
A9: s0 (varianza del residuo más reciente del VAR, marzo 2020 — ancla real) | C9: 0.0011994175
A11: Fecha | B11: M0_p05 | C11: M0_p25 | D11: M0_mediana | E11: M0_p75 | F11: M0_p95 | G11: M1_p05 | H11: M1_p25 | I11: M1_mediana | J11: M1_p75 | K11: M1_p95 | L11: M2_p05 | M11: M2_p25 | N11: M2_mediana | O11: M2_p75 | P11: M2_p95 | Q11: M3_p05 | R11: M3_p25 | S11: M3_mediana | T11: M3_p75 | U11: M3_p95 | V11: IGAE_observado
A12: 2020-04 | B12: -0.012124425 | C12: -0.0051611334 | D12: -0.00050930034 | E12: 0.0044677607 | F12: 0.012304514 | G12: -0.016563689 | H12: -0.0055420144 | I12: 3.2813471e-05 | J12: 0.0046365586 | K12: 0.013924701 | L12: -0.015105983 | M12: -0.0055842179 | N12: -0.00034384521 | O12: 0.0046346013 | P12: 0.01311174 | Q12: =L12+(-$C$5*SQRT($C$9)*SUMPRODUCT(TRANSPOSE(COVID_Escenarios!$C$53:$C$56),TANH(COVID_Escenarios!B61:E61)))+(-$C$7*SQRT($C$9)*TANH(INDEX(GDELT!$E$5:$E$52,MATCH(A12,GDELT!$A$5:$A$52,0))))-1.645*SQRT(($C$6*SQRT($C$9)*SUMPRODUCT(TRANSPOSE(COVID_Escenarios!$C$53:$C$56),TANH(ABS(COVID_Escenarios!B61:E61-MIN(COVID_Escenarios!B61:E61)))))^2+($C$8*SQRT($C$9)*TANH(ABS(INDEX(GDELT!$E$5:$E$52,MATCH(A12,GDELT!$A$5:$A$52,0)))))^2) | R12: =M12+(-$C$5*SQRT($C$9)*SUMPRODUCT(TRANSPOSE(COVID_Escenarios!$C$53:$C$56),TANH(COVID_Escenarios!B61:E61)))+(-$C$7*SQRT($C$9)*TANH(INDEX(GDELT!$E$5:$E$52,MATCH(A12,GDELT!$A$5:$A$52,0))))-0.675*SQRT(($C$6*SQRT($C$9)*SUMPRODUCT(TRANSPOSE(COVID_Escenarios!$C$53:$C$56),TANH(ABS(COVID_Escenarios!B61:E61-MIN(COVID_Escenarios!B61:E61)))))^2+($C$8*SQRT($C$9)*TANH(ABS(INDEX(GDELT!$E$5:$E$52,MATCH(A12,GDELT!$A$5:$A$52,0)))))^2) | S12: =N12+(-$C$5*SQRT($C$9)*SUMPRODUCT(TRANSPOSE(COVID_Escenarios!$C$53:$C$56),TANH(COVID_Escenarios!B61:E61)))+(-$C$7*SQRT($C$9)*TANH(INDEX(GDELT!$E$5:$E$52,MATCH(A12,GDELT!$A$5:$A$52,0)))) | T12: =O12+(-$C$5*SQRT($C$9)*SUMPRODUCT(TRANSPOSE(COVID_Escenarios!$C$53:$C$56),TANH(COVID_Escenarios!B61:E61)))+(-$C$7*SQRT($C$9)*TANH(INDEX(GDELT!$E$5:$E$52,MATCH(A12,GDELT!$A$5:$A$52,0))))+0.675*SQRT(($C$6*SQRT($C$9)*SUMPRODUCT(TRANSPOSE(COVID_Escenarios!$C$53:$C$56),TANH(ABS(COVID_Escenarios!B61:E61-MIN(COVID_Escenarios!B61:E61)))))^2+($C$8*SQRT($C$9)*TANH(ABS(INDEX(GDELT!$E$5:$E$52,MATCH(A12,GDELT!$A$5:$A$52,0)))))^2) | U12: =P12+(-$C$5*SQRT($C$9)*SUMPRODUCT(TRANSPOSE(COVID_Escenarios!$C$53:$C$56),TANH(COVID_Escenarios!B61:E61)))+(-$C$7*SQRT($C$9)*TANH(INDEX(GDELT!$E$5:$E$52,MATCH(A12,GDELT!$A$5:$A$52,0))))+1.645*SQRT(($C$6*SQRT($C$9)*SUMPRODUCT(TRANSPOSE(COVID_Escenarios!$C$53:$C$56),TANH(ABS(COVID_Escenarios!B61:E61-MIN(COVID_Escenarios!B61:E61)))))^2+($C$8*SQRT($C$9)*TANH(ABS(INDEX(GDELT!$E$5:$E$52,MATCH(A12,GDELT!$A$5:$A$52,0)))))^2) | V12: -0.20913616
A13: 2020-05 | B13: -0.015324099 | C13: -0.0084177665 | D13: -0.0032973678 | E13: 0.0014388068 | F13: 0.0087468921 | G13: -0.016682566 | H13: -0.007640296 | I13: -0.0030748137 | J13: 0.0016319136 | K13: 0.011175012 | L13: -0.016410525 | M13: -0.0075479143 | N13: -0.0031016074 | O13: 0.0015880106 | P13: 0.00974505 | Q13: =L13+(-$C$5*SQRT($C$9)*SUMPRODUCT(TRANSPOSE(COVID_Escenarios!$C$53:$C$56),TANH(COVID_Escenarios!B62:E62)))+(-$C$7*SQRT($C$9)*TANH(INDEX(GDELT!$E$5:$E$52,MATCH(A13,GDELT!$A$5:$A$52,0))))-1.645*SQRT(($C$6*SQRT($C$9)*SUMPRODUCT(TRANSPOSE(COVID_Escenarios!$C$53:$C$56),TANH(ABS(COVID_Escenarios!B62:E62-MIN(COVID_Escenarios!B62:E62)))))^2+($C$8*SQRT($C$9)*TANH(ABS(INDEX(GDELT!$E$5:$E$52,MATCH(A13,GDELT!$A$5:$A$52,0)))))^2) | R13: =M13+(-$C$5*SQRT($C$9)*SUMPRODUCT(TRANSPOSE(COVID_Escenarios!$C$53:$C$56),TANH(COVID_Escenarios!B62:E62)))+(-$C$7*SQRT($C$9)*TANH(INDEX(GDELT!$E$5:$E$52,MATCH(A13,GDELT!$A$5:$A$52,0))))-0.675*SQRT(($C$6*SQRT($C$9)*SUMPRODUCT(TRANSPOSE(COVID_Escenarios!$C$53:$C$56),TANH(ABS(COVID_Escenarios!B62:E62-MIN(COVID_Escenarios!B62:E62)))))^2+($C$8*SQRT($C$9)*TANH(ABS(INDEX(GDELT!$E$5:$E$52,MATCH(A13,GDELT!$A$5:$A$52,0)))))^2) | S13: =N13+(-$C$5*SQRT($C$9)*SUMPRODUCT(TRANSPOSE(COVID_Escenarios!$C$53:$C$56),TANH(COVID_Escenarios!B62:E62)))+(-$C$7*SQRT($C$9)*TANH(INDEX(GDELT!$E$5:$E$52,MATCH(A13,GDELT!$A$5:$A$52,0)))) | T13: =O13+(-$C$5*SQRT($C$9)*SUMPRODUCT(TRANSPOSE(COVID_Escenarios!$C$53:$C$56),TANH(COVID_Escenarios!B62:E62)))+(-$C$7*SQRT($C$9)*TANH(INDEX(GDELT!$E$5:$E$52,MATCH(A13,GDELT!$A$5:$A$52,0))))+0.675*SQRT(($C$6*SQRT($C$9)*SUMPRODUCT(TRANSPOSE(COVID_Escenarios!$C$53:$C$56),TANH(ABS(COVID_Escenarios!B62:E62-MIN(COVID_Escenarios!B62:E62)))))^2+($C$8*SQRT($C$9)*TANH(ABS(INDEX(GDELT!$E$5:$E$52,MATCH(A13,GDELT!$A$5:$A$52,0)))))^2) | U13: =P13+(-$C$5*SQRT($C$9)*SUMPRODUCT(TRANSPOSE(COVID_Escenarios!$C$53:$C$56),TANH(COVID_Escenarios!B62:E62)))+(-$C$7*SQRT($C$9)*TANH(INDEX(GDELT!$E$5:$E$52,MATCH(A13,GDELT!$A$5:$A$52,0))))+1.645*SQRT(($C$6*SQRT($C$9)*SUMPRODUCT(TRANSPOSE(COVID_Escenarios!$C$53:$C$56),TANH(ABS(COVID_Escenarios!B62:E62-MIN(COVID_Escenarios!B62:E62)))))^2+($C$8*SQRT($C$9)*TANH(ABS(INDEX(GDELT!$E$5:$E$52,MATCH(A13,GDELT!$A$5:$A$52,0)))))^2) | V13: -0.018833946
A14: 2020-06 | B14: -0.014871204 | C14: -0.0079695079 | D14: -0.00330794 | E14: 0.001671492 | F14: 0.0085197336 | G14: -0.015821733 | H14: -0.007635329 | I14: -0.0032245904 | J14: 0.0012485789 | K14: 0.0098643288 | L14: -0.01643868 | M14: -0.0077227544 | N14: -0.0033868014 | O14: 0.00064663774 | P14: 0.0091342744 | Q14: =L14+(-$C$5*SQRT($C$9)*SUMPRODUCT(TRANSPOSE(COVID_Escenarios!$C$53:$C$56),TANH(COVID_Escenarios!B63:E63)))+(-$C$7*SQRT($C$9)*TANH(INDEX(GDELT!$E$5:$E$52,MATCH(A14,GDELT!$A$5:$A$52,0))))-1.645*SQRT(($C$6*SQRT($C$9)*SUMPRODUCT(TRANSPOSE(COVID_Escenarios!$C$53:$C$56),TANH(ABS(COVID_Escenarios!B63:E63-MIN(COVID_Escenarios!B63:E63)))))^2+($C$8*SQRT($C$9)*TANH(ABS(INDEX(GDELT!$E$5:$E$52,MATCH(A14,GDELT!$A$5:$A$52,0)))))^2) | R14: =M14+(-$C$5*SQRT($C$9)*SUMPRODUCT(TRANSPOSE(COVID_Escenarios!$C$53:$C$56),TANH(COVID_Escenarios!B63:E63)))+(-$C$7*SQRT($C$9)*TANH(INDEX(GDELT!$E$5:$E$52,MATCH(A14,GDELT!$A$5:$A$52,0))))-0.675*SQRT(($C$6*SQRT($C$9)*SUMPRODUCT(TRANSPOSE(COVID_Escenarios!$C$53:$C$56),TANH(ABS(COVID_Escenarios!B63:E63-MIN(COVID_Escenarios!B63:E63)))))^2+($C$8*SQRT($C$9)*TANH(ABS(INDEX(GDELT!$E$5:$E$52,MATCH(A14,GDELT!$A$5:$A$52,0)))))^2) | S14: =N14+(-$C$5*SQRT($C$9)*SUMPRODUCT(TRANSPOSE(COVID_Escenarios!$C$53:$C$56),TANH(COVID_Escenarios!B63:E63)))+(-$C$7*SQRT($C$9)*TANH(INDEX(GDELT!$E$5:$E$52,MATCH(A14,GDELT!$A$5:$A$52,0)))) | T14: =O14+(-$C$5*SQRT($C$9)*SUMPRODUCT(TRANSPOSE(COVID_Escenarios!$C$53:$C$56),TANH(COVID_Escenarios!B63:E63)))+(-$C$7*SQRT($C$9)*TANH(INDEX(GDELT!$E$5:$E$52,MATCH(A14,GDELT!$A$5:$A$52,0))))+0.675*SQRT(($C$6*SQRT($C$9)*SUMPRODUCT(TRANSPOSE(COVID_Escenarios!$C$53:$C$56),TANH(ABS(COVID_Escenarios!B63:E63-MIN(COVID_Escenarios!B63:E63)))))^2+($C$8*SQRT($C$9)*TANH(ABS(INDEX(GDELT!$E$5:$E$52,MATCH(A14,GDELT!$A$5:$A$52,0)))))^2) | U14: =P14+(-$C$5*SQRT($C$9)*SUMPRODUCT(TRANSPOSE(COVID_Escenarios!$C$53:$C$56),TANH(COVID_Escenarios!B63:E63)))+(-$C$7*SQRT($C$9)*TANH(INDEX(GDELT!$E$5:$E$52,MATCH(A14,GDELT!$A$5:$A$52,0))))+1.645*SQRT(($C$6*SQRT($C$9)*SUMPRODUCT(TRANSPOSE(COVID_Escenarios!$C$53:$C$56),TANH(ABS(COVID_Escenarios!B63:E63-MIN(COVID_Escenarios!B63:E63)))))^2+($C$8*SQRT($C$9)*TANH(ABS(INDEX(GDELT!$E$5:$E$52,MATCH(A14,GDELT!$A$5:$A$52,0)))))^2) | V14: 0.11203513
A15: 2020-07 | B15: -0.014878014 | C15: -0.0071400011 | D15: -0.0027090391 | E15: 0.0021712968 | F15: 0.0088388516 | G15: -0.015242189 | H15: -0.0066871566 | I15: -0.002689158 | J15: 0.0013483298 | K15: 0.0089865827 | L15: -0.014571097 | M15: -0.0065715617 | N15: -0.0026215762 | O15: 0.0010319818 | P15: 0.0088136814 | Q15: =L15+(-$C$5*SQRT($C$9)*SUMPRODUCT(TRANSPOSE(COVID_Escenarios!$C$53:$C$56),TANH(COVID_Escenarios!B64:E64)))+(-$C$7*SQRT($C$9)*TANH(INDEX(GDELT!$E$5:$E$52,MATCH(A15,GDELT!$A$5:$A$52,0))))-1.645*SQRT(($C$6*SQRT($C$9)*SUMPRODUCT(TRANSPOSE(COVID_Escenarios!$C$53:$C$56),TANH(ABS(COVID_Escenarios!B64:E64-MIN(COVID_Escenarios!B64:E64)))))^2+($C$8*SQRT($C$9)*TANH(ABS(INDEX(GDELT!$E$5:$E$52,MATCH(A15,GDELT!$A$5:$A$52,0)))))^2) | R15: =M15+(-$C$5*SQRT($C$9)*SUMPRODUCT(TRANSPOSE(COVID_Escenarios!$C$53:$C$56),TANH(COVID_Escenarios!B64:E64)))+(-$C$7*SQRT($C$9)*TANH(INDEX(GDELT!$E$5:$E$52,MATCH(A15,GDELT!$A$5:$A$52,0))))-0.675*SQRT(($C$6*SQRT($C$9)*SUMPRODUCT(TRANSPOSE(COVID_Escenarios!$C$53:$C$56),TANH(ABS(COVID_Escenarios!B64:E64-MIN(COVID_Escenarios!B64:E64)))))^2+($C$8*SQRT($C$9)*TANH(ABS(INDEX(GDELT!$E$5:$E$52,MATCH(A15,GDELT!$A$5:$A$52,0)))))^2) | S15: =N15+(-$C$5*SQRT($C$9)*SUMPRODUCT(TRANSPOSE(COVID_Escenarios!$C$53:$C$56),TANH(COVID_Escenarios!B64:E64)))+(-$C$7*SQRT($C$9)*TANH(INDEX(GDELT!$E$5:$E$52,MATCH(A15,GDELT!$A$5:$A$52,0)))) | T15: =O15+(-$C$5*SQRT($C$9)*SUMPRODUCT(TRANSPOSE(COVID_Escenarios!$C$53:$C$56),TANH(COVID_Escenarios!B64:E64)))+(-$C$7*SQRT($C$9)*TANH(INDEX(GDELT!$E$5:$E$52,MATCH(A15,GDELT!$A$5:$A$52,0))))+0.675*SQRT(($C$6*SQRT($C$9)*SUMPRODUCT(TRANSPOSE(COVID_Escenarios!$C$53:$C$56),TANH(ABS(COVID_Escenarios!B64:E64-MIN(COVID_Escenarios!B64:E64)))))^2+($C$8*SQRT($C$9)*TANH(ABS(INDEX(GDELT!$E$5:$E$52,MATCH(A15,GDELT!$A$5:$A$52,0)))))^2) | U15: =P15+(-$C$5*SQRT($C$9)*SUMPRODUCT(TRANSPOSE(COVID_Escenarios!$C$53:$C$56),TANH(COVID_Escenarios!B64:E64)))+(-$C$7*SQRT($C$9)*TANH(INDEX(GDELT!$E$5:$E$52,MATCH(A15,GDELT!$A$5:$A$52,0))))+1.645*SQRT(($C$6*SQRT($C$9)*SUMPRODUCT(TRANSPOSE(COVID_Escenarios!$C$53:$C$56),TANH(ABS(COVID_Escenarios!B64:E64-MIN(COVID_Escenarios!B64:E64)))))^2+($C$8*SQRT($C$9)*TANH(ABS(INDEX(GDELT!$E$5:$E$52,MATCH(A15,GDELT!$A$5:$A$52,0)))))^2) | V15: 0.049403613
A16: 2020-08 | B16: -0.013802903 | C16: -0.0074340037 | D16: -0.0024233755 | E16: 0.0023385363 | F16: 0.0095950767 | G16: -0.014098291 | H16: -0.0062743663 | I16: -0.0022584432 | J16: 0.0015356109 | K16: 0.0094935563 | L16: -0.01339696 | M16: -0.0059939727 | N16: -0.0022076462 | O16: 0.0018720351 | P16: 0.010212154 | Q16: =L16+(-$C$5*SQRT($C$9)*SUMPRODUCT(TRANSPOSE(COVID_Escenarios!$C$53:$C$56),TANH(COVID_Escenarios!B65:E65)))+(-$C$7*SQRT($C$9)*TANH(INDEX(GDELT!$E$5:$E$52,MATCH(A16,GDELT!$A$5:$A$52,0))))-1.645*SQRT(($C$6*SQRT($C$9)*SUMPRODUCT(TRANSPOSE(COVID_Escenarios!$C$53:$C$56),TANH(ABS(COVID_Escenarios!B65:E65-MIN(COVID_Escenarios!B65:E65)))))^2+($C$8*SQRT($C$9)*TANH(ABS(INDEX(GDELT!$E$5:$E$52,MATCH(A16,GDELT!$A$5:$A$52,0)))))^2) | R16: =M16+(-$C$5*SQRT($C$9)*SUMPRODUCT(TRANSPOSE(COVID_Escenarios!$C$53:$C$56),TANH(COVID_Escenarios!B65:E65)))+(-$C$7*SQRT($C$9)*TANH(INDEX(GDELT!$E$5:$E$52,MATCH(A16,GDELT!$A$5:$A$52,0))))-0.675*SQRT(($C$6*SQRT($C$9)*SUMPRODUCT(TRANSPOSE(COVID_Escenarios!$C$53:$C$56),TANH(ABS(COVID_Escenarios!B65:E65-MIN(COVID_Escenarios!B65:E65)))))^2+($C$8*SQRT($C$9)*TANH(ABS(INDEX(GDELT!$E$5:$E$52,MATCH(A16,GDELT!$A$5:$A$52,0)))))^2) | S16: =N16+(-$C$5*SQRT($C$9)*SUMPRODUCT(TRANSPOSE(COVID_Escenarios!$C$53:$C$56),TANH(COVID_Escenarios!B65:E65)))+(-$C$7*SQRT($C$9)*TANH(INDEX(GDELT!$E$5:$E$52,MATCH(A16,GDELT!$A$5:$A$52,0)))) | T16: =O16+(-$C$5*SQRT($C$9)*SUMPRODUCT(TRANSPOSE(COVID_Escenarios!$C$53:$C$56),TANH(COVID_Escenarios!B65:E65)))+(-$C$7*SQRT($C$9)*TANH(INDEX(GDELT!$E$5:$E$52,MATCH(A16,GDELT!$A$5:$A$52,0))))+0.675*SQRT(($C$6*SQRT($C$9)*SUMPRODUCT(TRANSPOSE(COVID_Escenarios!$C$53:$C$56),TANH(ABS(COVID_Escenarios!B65:E65-MIN(COVID_Escenarios!B65:E65)))))^2+($C$8*SQRT($C$9)*TANH(ABS(INDEX(GDELT!$E$5:$E$52,MATCH(A16,GDELT!$A$5:$A$52,0)))))^2) | U16: =P16+(-$C$5*SQRT($C$9)*SUMPRODUCT(TRANSPOSE(COVID_Escenarios!$C$53:$C$56),TANH(COVID_Escenarios!B65:E65)))+(-$C$7*SQRT($C$9)*TANH(INDEX(GDELT!$E$5:$E$52,MATCH(A16,GDELT!$A$5:$A$52,0))))+1.645*SQRT(($C$6*SQRT($C$9)*SUMPRODUCT(TRANSPOSE(COVID_Escenarios!$C$53:$C$56),TANH(ABS(COVID_Escenarios!B65:E65-MIN(COVID_Escenarios!B65:E65)))))^2+($C$8*SQRT($C$9)*TANH(ABS(INDEX(GDELT!$E$5:$E$52,MATCH(A16,GDELT!$A$5:$A$52,0)))))^2) | V16: 0.02893197
A17: 2020-09 | B17: -0.013652485 | C17: -0.0068265171 | D17: -0.0021152867 | E17: 0.0026690395 | F17: 0.0097961734 | G17: -0.013593138 | H17: -0.006052925 | I17: -0.0021411574 | J17: 0.0012793684 | K17: 0.0090379426 | L17: -0.013750292 | M17: -0.006010816 | N17: -0.0021166462 | O17: 0.0015553219 | P17: 0.0089072861 | Q17: =L17+(-$C$5*SQRT($C$9)*SUMPRODUCT(TRANSPOSE(COVID_Escenarios!$C$53:$C$56),TANH(COVID_Escenarios!B66:E66)))+(-$C$7*SQRT($C$9)*TANH(INDEX(GDELT!$E$5:$E$52,MATCH(A17,GDELT!$A$5:$A$52,0))))-1.645*SQRT(($C$6*SQRT($C$9)*SUMPRODUCT(TRANSPOSE(COVID_Escenarios!$C$53:$C$56),TANH(ABS(COVID_Escenarios!B66:E66-MIN(COVID_Escenarios!B66:E66)))))^2+($C$8*SQRT($C$9)*TANH(ABS(INDEX(GDELT!$E$5:$E$52,MATCH(A17,GDELT!$A$5:$A$52,0)))))^2) | R17: =M17+(-$C$5*SQRT($C$9)*SUMPRODUCT(TRANSPOSE(COVID_Escenarios!$C$53:$C$56),TANH(COVID_Escenarios!B66:E66)))+(-$C$7*SQRT($C$9)*TANH(INDEX(GDELT!$E$5:$E$52,MATCH(A17,GDELT!$A$5:$A$52,0))))-0.675*SQRT(($C$6*SQRT($C$9)*SUMPRODUCT(TRANSPOSE(COVID_Escenarios!$C$53:$C$56),TANH(ABS(COVID_Escenarios!B66:E66-MIN(COVID_Escenarios!B66:E66)))))^2+($C$8*SQRT($C$9)*TANH(ABS(INDEX(GDELT!$E$5:$E$52,MATCH(A17,GDELT!$A$5:$A$52,0)))))^2) | S17: =N17+(-$C$5*SQRT($C$9)*SUMPRODUCT(TRANSPOSE(COVID_Escenarios!$C$53:$C$56),TANH(COVID_Escenarios!B66:E66)))+(-$C$7*SQRT($C$9)*TANH(INDEX(GDELT!$E$5:$E$52,MATCH(A17,GDELT!$A$5:$A$52,0)))) | T17: =O17+(-$C$5*SQRT($C$9)*SUMPRODUCT(TRANSPOSE(COVID_Escenarios!$C$53:$C$56),TANH(COVID_Escenarios!B66:E66)))+(-$C$7*SQRT($C$9)*TANH(INDEX(GDELT!$E$5:$E$52,MATCH(A17,GDELT!$A$5:$A$52,0))))+0.675*SQRT(($C$6*SQRT($C$9)*SUMPRODUCT(TRANSPOSE(COVID_Escenarios!$C$53:$C$56),TANH(ABS(COVID_Escenarios!B66:E66-MIN(COVID_Escenarios!B66:E66)))))^2+($C$8*SQRT($C$9)*TANH(ABS(INDEX(GDELT!$E$5:$E$52,MATCH(A17,GDELT!$A$5:$A$52,0)))))^2) | U17: =P17+(-$C$5*SQRT($C$9)*SUMPRODUCT(TRANSPOSE(COVID_Escenarios!$C$53:$C$56),TANH(COVID_Escenarios!B66:E66)))+(-$C$7*SQRT($C$9)*TANH(INDEX(GDELT!$E$5:$E$52,MATCH(A17,GDELT!$A$5:$A$52,0))))+1.645*SQRT(($C$6*SQRT($C$9)*SUMPRODUCT(TRANSPOSE(COVID_Escenarios!$C$53:$C$56),TANH(ABS(COVID_Escenarios!B66:E66-MIN(COVID_Escenarios!B66:E66)))))^2+($C$8*SQRT($C$9)*TANH(ABS(INDEX(GDELT!$E$5:$E$52,MATCH(A17,GDELT!$A$5:$A$52,0)))))^2) | V17: 0.026760278
A18: 2020-10 | B18: -0.01399861 | C18: -0.0064590477 | D18: -0.001447018 | E18: 0.0032033773 | F18: 0.010036754 | G18: -0.014062428 | H18: -0.0055614388 | I18: -0.0016638343 | J18: 0.0020055117 | K18: 0.0099385711 | L18: -0.0132624 | M18: -0.0056571993 | N18: -0.0017290008 | O18: 0.002015261 | P18: 0.0092607989 | Q18: =L18+(-$C$5*SQRT($C$9)*SUMPRODUCT(TRANSPOSE(COVID_Escenarios!$C$53:$C$56),TANH(COVID_Escenarios!B67:E67)))+(-$C$7*SQRT($C$9)*TANH(INDEX(GDELT!$E$5:$E$52,MATCH(A18,GDELT!$A$5:$A$52,0))))-1.645*SQRT(($C$6*SQRT($C$9)*SUMPRODUCT(TRANSPOSE(COVID_Escenarios!$C$53:$C$56),TANH(ABS(COVID_Escenarios!B67:E67-MIN(COVID_Escenarios!B67:E67)))))^2+($C$8*SQRT($C$9)*TANH(ABS(INDEX(GDELT!$E$5:$E$52,MATCH(A18,GDELT!$A$5:$A$52,0)))))^2) | R18: =M18+(-$C$5*SQRT($C$9)*SUMPRODUCT(TRANSPOSE(COVID_Escenarios!$C$53:$C$56),TANH(COVID_Escenarios!B67:E67)))+(-$C$7*SQRT($C$9)*TANH(INDEX(GDELT!$E$5:$E$52,MATCH(A18,GDELT!$A$5:$A$52,0))))-0.675*SQRT(($C$6*SQRT($C$9)*SUMPRODUCT(TRANSPOSE(COVID_Escenarios!$C$53:$C$56),TANH(ABS(COVID_Escenarios!B67:E67-MIN(COVID_Escenarios!B67:E67)))))^2+($C$8*SQRT($C$9)*TANH(ABS(INDEX(GDELT!$E$5:$E$52,MATCH(A18,GDELT!$A$5:$A$52,0)))))^2) | S18: =N18+(-$C$5*SQRT($C$9)*SUMPRODUCT(TRANSPOSE(COVID_Escenarios!$C$53:$C$56),TANH(COVID_Escenarios!B67:E67)))+(-$C$7*SQRT($C$9)*TANH(INDEX(GDELT!$E$5:$E$52,MATCH(A18,GDELT!$A$5:$A$52,0)))) | T18: =O18+(-$C$5*SQRT($C$9)*SUMPRODUCT(TRANSPOSE(COVID_Escenarios!$C$53:$C$56),TANH(COVID_Escenarios!B67:E67)))+(-$C$7*SQRT($C$9)*TANH(INDEX(GDELT!$E$5:$E$52,MATCH(A18,GDELT!$A$5:$A$52,0))))+0.675*SQRT(($C$6*SQRT($C$9)*SUMPRODUCT(TRANSPOSE(COVID_Escenarios!$C$53:$C$56),TANH(ABS(COVID_Escenarios!B67:E67-MIN(COVID_Escenarios!B67:E67)))))^2+($C$8*SQRT($C$9)*TANH(ABS(INDEX(GDELT!$E$5:$E$52,MATCH(A18,GDELT!$A$5:$A$52,0)))))^2) | U18: =P18+(-$C$5*SQRT($C$9)*SUMPRODUCT(TRANSPOSE(COVID_Escenarios!$C$53:$C$56),TANH(COVID_Escenarios!B67:E67)))+(-$C$7*SQRT($C$9)*TANH(INDEX(GDELT!$E$5:$E$52,MATCH(A18,GDELT!$A$5:$A$52,0))))+1.645*SQRT(($C$6*SQRT($C$9)*SUMPRODUCT(TRANSPOSE(COVID_Escenarios!$C$53:$C$56),TANH(ABS(COVID_Escenarios!B67:E67-MIN(COVID_Escenarios!B67:E67)))))^2+($C$8*SQRT($C$9)*TANH(ABS(INDEX(GDELT!$E$5:$E$52,MATCH(A18,GDELT!$A$5:$A$52,0)))))^2) | V18: 0.010593538
A19: 2020-11 | B19: -0.012983104 | C19: -0.0063916144 | D19: -0.0015952313 | E19: 0.0034675972 | F19: 0.010227752 | G19: -0.01234577 | H19: -0.0053184536 | I19: -0.0014358057 | J19: 0.002410804 | K19: 0.0092759262 | L19: -0.013439805 | M19: -0.0052192828 | N19: -0.0014273955 | O19: 0.0025758214 | P19: 0.010443766 | Q19: =L19+(-$C$5*SQRT($C$9)*SUMPRODUCT(TRANSPOSE(COVID_Escenarios!$C$53:$C$56),TANH(COVID_Escenarios!B68:E68)))+(-$C$7*SQRT($C$9)*TANH(INDEX(GDELT!$E$5:$E$52,MATCH(A19,GDELT!$A$5:$A$52,0))))-1.645*SQRT(($C$6*SQRT($C$9)*SUMPRODUCT(TRANSPOSE(COVID_Escenarios!$C$53:$C$56),TANH(ABS(COVID_Escenarios!B68:E68-MIN(COVID_Escenarios!B68:E68)))))^2+($C$8*SQRT($C$9)*TANH(ABS(INDEX(GDELT!$E$5:$E$52,MATCH(A19,GDELT!$A$5:$A$52,0)))))^2) | R19: =M19+(-$C$5*SQRT($C$9)*SUMPRODUCT(TRANSPOSE(COVID_Escenarios!$C$53:$C$56),TANH(COVID_Escenarios!B68:E68)))+(-$C$7*SQRT($C$9)*TANH(INDEX(GDELT!$E$5:$E$52,MATCH(A19,GDELT!$A$5:$A$52,0))))-0.675*SQRT(($C$6*SQRT($C$9)*SUMPRODUCT(TRANSPOSE(COVID_Escenarios!$C$53:$C$56),TANH(ABS(COVID_Escenarios!B68:E68-MIN(COVID_Escenarios!B68:E68)))))^2+($C$8*SQRT($C$9)*TANH(ABS(INDEX(GDELT!$E$5:$E$52,MATCH(A19,GDELT!$A$5:$A$52,0)))))^2) | S19: =N19+(-$C$5*SQRT($C$9)*SUMPRODUCT(TRANSPOSE(COVID_Escenarios!$C$53:$C$56),TANH(COVID_Escenarios!B68:E68)))+(-$C$7*SQRT($C$9)*TANH(INDEX(GDELT!$E$5:$E$52,MATCH(A19,GDELT!$A$5:$A$52,0)))) | T19: =O19+(-$C$5*SQRT($C$9)*SUMPRODUCT(TRANSPOSE(COVID_Escenarios!$C$53:$C$56),TANH(COVID_Escenarios!B68:E68)))+(-$C$7*SQRT($C$9)*TANH(INDEX(GDELT!$E$5:$E$52,MATCH(A19,GDELT!$A$5:$A$52,0))))+0.675*SQRT(($C$6*SQRT($C$9)*SUMPRODUCT(TRANSPOSE(COVID_Escenarios!$C$53:$C$56),TANH(ABS(COVID_Escenarios!B68:E68-MIN(COVID_Escenarios!B68:E68)))))^2+($C$8*SQRT($C$9)*TANH(ABS(INDEX(GDELT!$E$5:$E$52,MATCH(A19,GDELT!$A$5:$A$52,0)))))^2) | U19: =P19+(-$C$5*SQRT($C$9)*SUMPRODUCT(TRANSPOSE(COVID_Escenarios!$C$53:$C$56),TANH(COVID_Escenarios!B68:E68)))+(-$C$7*SQRT($C$9)*TANH(INDEX(GDELT!$E$5:$E$52,MATCH(A19,GDELT!$A$5:$A$52,0))))+1.645*SQRT(($C$6*SQRT($C$9)*SUMPRODUCT(TRANSPOSE(COVID_Escenarios!$C$53:$C$56),TANH(ABS(COVID_Escenarios!B68:E68-MIN(COVID_Escenarios!B68:E68)))))^2+($C$8*SQRT($C$9)*TANH(ABS(INDEX(GDELT!$E$5:$E$52,MATCH(A19,GDELT!$A$5:$A$52,0)))))^2) | V19: 0.0077044426
A20: 2020-12 | B20: -0.013449681 | C20: -0.0063422159 | D20: -0.0013557526 | E20: 0.0033920873 | F20: 0.010531388 | G20: -0.012636372 | H20: -0.0051550092 | I20: -0.001374916 | J20: 0.0024026554 | K20: 0.0097014033 | L20: -0.01248396 | M20: -0.0049288886 | N20: -0.0010653681 | O20: 0.0028122414 | P20: 0.010420371 | Q20: =L20+(-$C$5*SQRT($C$9)*SUMPRODUCT(TRANSPOSE(COVID_Escenarios!$C$53:$C$56),TANH(COVID_Escenarios!B69:E69)))+(-$C$7*SQRT($C$9)*TANH(INDEX(GDELT!$E$5:$E$52,MATCH(A20,GDELT!$A$5:$A$52,0))))-1.645*SQRT(($C$6*SQRT($C$9)*SUMPRODUCT(TRANSPOSE(COVID_Escenarios!$C$53:$C$56),TANH(ABS(COVID_Escenarios!B69:E69-MIN(COVID_Escenarios!B69:E69)))))^2+($C$8*SQRT($C$9)*TANH(ABS(INDEX(GDELT!$E$5:$E$52,MATCH(A20,GDELT!$A$5:$A$52,0)))))^2) | R20: =M20+(-$C$5*SQRT($C$9)*SUMPRODUCT(TRANSPOSE(COVID_Escenarios!$C$53:$C$56),TANH(COVID_Escenarios!B69:E69)))+(-$C$7*SQRT($C$9)*TANH(INDEX(GDELT!$E$5:$E$52,MATCH(A20,GDELT!$A$5:$A$52,0))))-0.675*SQRT(($C$6*SQRT($C$9)*SUMPRODUCT(TRANSPOSE(COVID_Escenarios!$C$53:$C$56),TANH(ABS(COVID_Escenarios!B69:E69-MIN(COVID_Escenarios!B69:E69)))))^2+($C$8*SQRT($C$9)*TANH(ABS(INDEX(GDELT!$E$5:$E$52,MATCH(A20,GDELT!$A$5:$A$52,0)))))^2) | S20: =N20+(-$C$5*SQRT($C$9)*SUMPRODUCT(TRANSPOSE(COVID_Escenarios!$C$53:$C$56),TANH(COVID_Escenarios!B69:E69)))+(-$C$7*SQRT($C$9)*TANH(INDEX(GDELT!$E$5:$E$52,MATCH(A20,GDELT!$A$5:$A$52,0)))) | T20: =O20+(-$C$5*SQRT($C$9)*SUMPRODUCT(TRANSPOSE(COVID_Escenarios!$C$53:$C$56),TANH(COVID_Escenarios!B69:E69)))+(-$C$7*SQRT($C$9)*TANH(INDEX(GDELT!$E$5:$E$52,MATCH(A20,GDELT!$A$5:$A$52,0))))+0.675*SQRT(($C$6*SQRT($C$9)*SUMPRODUCT(TRANSPOSE(COVID_Escenarios!$C$53:$C$56),TANH(ABS(COVID_Escenarios!B69:E69-MIN(COVID_Escenarios!B69:E69)))))^2+($C$8*SQRT($C$9)*TANH(ABS(INDEX(GDELT!$E$5:$E$52,MATCH(A20,GDELT!$A$5:$A$52,0)))))^2) | U20: =P20+(-$C$5*SQRT($C$9)*SUMPRODUCT(TRANSPOSE(COVID_Escenarios!$C$53:$C$56),TANH(COVID_Escenarios!B69:E69)))+(-$C$7*SQRT($C$9)*TANH(INDEX(GDELT!$E$5:$E$52,MATCH(A20,GDELT!$A$5:$A$52,0))))+1.645*SQRT(($C$6*SQRT($C$9)*SUMPRODUCT(TRANSPOSE(COVID_Escenarios!$C$53:$C$56),TANH(ABS(COVID_Escenarios!B69:E69-MIN(COVID_Escenarios!B69:E69)))))^2+($C$8*SQRT($C$9)*TANH(ABS(INDEX(GDELT!$E$5:$E$52,MATCH(A20,GDELT!$A$5:$A$52,0)))))^2) | V20: -0.0029457776

Sheet Graficas
A1: Escalera de pronóstico — M0 a M3 (todas ligadas a la hoja Modelos)
A58: Nota: por limitación de la librería usada para graficar (openpyxl), las bandas se muestran como P5 y P95 en líneas punteadas (no como área sombreada continua); los valores exactos de P25/P75 están en la hoja Modelos. Mediana en línea gruesa de color, IGAE observado en negro.

Sheet Metodologia
A1: Metodología, validaciones y hallazgos honestos
A3: 1) Selección de variables — CV10 R² por rezago (0/1/2 meses)
A4: Variable | B4: Rezago 0 | C4: Rezago 1 | D4: Rezago 2
A5: ANTAD_mom | B5: -0.64765634 | C5: -0.12546939 | D5: -0.11869813
A6: AUTOS_mom | B6: -0.79259282 | C6: -0.15031767 | D6: -0.097104876
A7: ActividadIndustrial_mom | B7: 0.50805566 | C7: -0.10586155 | D7: -0.11355223
A8: BMV_mom | B8: -0.094433609 | C8: -0.12135818 | D8: -0.11882347
A9: Balanza_mom | B9: -0.2523858 | C9: -0.083420741 | D9: -0.074470823
A10: Desempleo_mom | B10: -0.29367131 | C10: -0.075180399 | D10: -0.24024233
A11: EPU_mom | B11: -0.055536128 | C11: -0.12343393 | D11: -0.054476006
A12: FBCF_mom | B12: -0.25625385 | C12: -0.10663357 | D12: -0.10041901
A13: IMCP_mom | B13: 0.048419466 | C13: -0.13137008 | D13: -0.11085801
A14: IMSS_mom | B14: -0.44392176 | C14: -0.062056054 | D14: -0.36599924
A15: INDPRO_mom | B15: -0.39548449 | C15: -0.036365471 | D15: -0.1617992
A16: INPC_mom | B16: -0.12880977 | C16: -0.087482819 | D16: -0.063038367
... A19: TIIE_mom | B19: -0.092298828 | C19: -0.08988535 | D19: -0.14602643
A21: Hallazgo: solo ActividadIndustrial (R²≈0.50, pero mismo rezago de publicación que IGAE — no sirve para nowcasting) e IMSS (R²≈0.06, rezago 12 días) superan cero. El resto no muestra señal lineal univariada positiva.
A24: 2) Calendario de publicación (vintage)
A25: Variable | B25: Rezago (días) | C25: Confianza | D25: Nota
A26: IGAE | B26: 56 | C26: alta_usuario | D26: INEGI. Dado por el usuario como verificado; chequeo independiente esta sesion via busqueda web sugiere ~53 dias (calendario de difusion INEGI). Rango de incertidumbre [53,56].
A27: ActividadIndustrial | B27: 56 | C27: alta_usuario | D27: INEGI, mismo comunicado que IGAE (se publican el mismo dia).
A28: FBCF | B28: 67 | C28: alta_usuario | D28: INEGI, comunicado APARTE del de IGAE (no el mismo dia).
A29: IMCP | B29: 67 | C29: alta_usuario | D29: Indicador Mensual del Consumo Privado, INEGI, mismo comunicado que FBCF.
A30: ANTAD | B30: 11 | C30: alta_usuario | D30: Ventas mismas tiendas ANTAD, asociacion privada, publicacion rapida.
A31: TARJETAS | B31: 11 | C31: supuesto | D31: Indicador de consumo con tarjetas. Sin fuente primaria verificada esta sesion; se asume el mismo rezago que ANTAD (privado, rubro similar de consumo) como cota razonable -- tratar con cautela.
A32: AUTOS | B32: 5 | C32: alta_usuario | D32: Registro Administrativo de la Industria Automotriz de Vehiculos Ligeros (INEGI/AMIA), de las publicaciones mas rapidas.
A33: IMSS | B33: 12 | C33: alta_usuario | D33: Puestos de trabajo afiliados al IMSS, publicacion administrativa rapida.
A34: Balanza | B34: 26 | C34: alta_usuario | D34: Balanza comercial, INEGI/Banxico.
A35: INDPRO | B35: 16 | C35: alta_sesion | D35: Corregido en esta sesion: Federal Reserve G.17, ~15-17 dias segun calendario 2026 (fuente: federalreserve.gov/releases/g17/). El supuesto previo de 45 dias NO estaba confirmado y era incorrecto.
A36: BMV | B36: 0 | C36: alta_sesion | D36: Indice bursatil, dato de mercado disponible el mismo dia (t+0).
A37: TC | B37: 1 | C37: alta_sesion | D37: Tipo de cambio FIX, Banxico publica con 1 dia habil de rezago.
... A43: GDELT | B43: 0 | C43: alta_sesion | D43: GDELT GKG 2.1 se actualiza cada 15 minutos; disponible casi en tiempo real (t+0).
A45: 3) Validación de puentes (LOO/CV) — todas NEGATIVAS, incluidas igual por instrucción
A46: Puente LP (abril, ridge): LOO-CV R² = -0.0148
A47: Puente LP (mayo, ridge): LOO-CV R² = -0.0129
A48: GBM tarjetas (ANTAD/AUTOS/IMSS/TARJETAS): CV10 R² = -0.0477
A49: GDELT (media del residuo VAR): CV5 R² = -0.2128
A50: GDELT (varianza del residuo VAR): CV5 R² = -0.1918
A51: Ninguno de estos modelos supera a la media histórica del residuo en validación honesta. El puente LP y GBM se dejan con su corrección conservadora (M2). GDELT se fuerza al ensamble de M3 por instrucción expresa del usuario, vía z-score de tono contra línea base 2017-2019, documentado aquí sin maquillar el resultado de su validación.
A53: 4) Pesos bayesianos de backcast de escenarios epidemiológicos
...
